2019-12-12 16:57:00,121 | DEBUG    | 0144 | Exception
2019-12-12 16:57:00,122 | ERROR    | 0145 | File not found exception [Errno 2] No such file or directory: 'C:/Users/rmore/Documents/equity-personneldb-npxfiling/data/documents/0000880195-18-000149.dissem'
2019-12-12 16:57:00,122 | DEBUG    | 0065 | Exception in parsing 
2019-12-12 16:57:00,122 | DEBUG    | 0066 | local variable 's' referenced before assignment
2019-12-12 16:58:16,320 | DEBUG    | 0144 | Exception
2019-12-12 16:58:16,320 | ERROR    | 0145 | File not found exception list index out of range
2019-12-12 16:58:36,249 | DEBUG    | 0103 | Exception in replacing empty
2019-12-12 16:58:36,251 | DEBUG    | 0065 | Exception in parsing 
2019-12-12 16:58:36,251 | DEBUG    | 0066 | local variable 'final_df' referenced before assignment
2019-12-12 17:01:02,973 | INFO     | 0422 | Concatenation start at2019-12-12 17:01:02.973429
2019-12-12 17:01:02,988 | INFO     | 0439 | Concatenation complete at2019-12-12 17:01:02.988389
2019-12-12 17:01:02,989 | INFO     | 0442 | merge start at2019-12-12 17:01:02.989384
2019-12-12 17:01:02,992 | INFO     | 0444 | merge end at2019-12-12 17:01:02.992378
2019-12-12 17:01:03,012 | INFO     | 0478 | Before connection establish for db
2019-12-12 17:01:03,014 | ERROR    | 0492 | Insertion into database failed for accession_no:0001193125-18-262943-(pyodbc.InterfaceError) ('IM002', '[IM002] [Microsoft][ODBC Driver Manager] Data source name not found and no default driver specified (0) (SQLDriverConnect)')
(Background on this error at: http://sqlalche.me/e/rvf5)
2019-12-12 17:01:03,014 | DEBUG    | 0065 | Exception in parsing 
2019-12-12 17:01:03,014 | DEBUG    | 0066 | local variable 'conn' referenced before assignment
2019-12-12 17:05:04,043 | INFO     | 0422 | Concatenation start at2019-12-12 17:05:04.043701
2019-12-12 17:05:04,063 | INFO     | 0439 | Concatenation complete at2019-12-12 17:05:04.063648
2019-12-12 17:05:04,065 | INFO     | 0442 | merge start at2019-12-12 17:05:04.065643
2019-12-12 17:05:04,067 | INFO     | 0444 | merge end at2019-12-12 17:05:04.067641
2019-12-12 17:05:04,093 | INFO     | 0478 | Before connection establish for db
2019-12-12 17:05:04,095 | ERROR    | 0492 | Insertion into database failed for accession_no:0001193125-18-262957-(pyodbc.InterfaceError) ('IM002', '[IM002] [Microsoft][ODBC Driver Manager] Data source name not found and no default driver specified (0) (SQLDriverConnect)')
(Background on this error at: http://sqlalche.me/e/rvf5)
2019-12-12 17:05:04,095 | DEBUG    | 0065 | Exception in parsing 
2019-12-12 17:05:04,095 | DEBUG    | 0066 | local variable 'conn' referenced before assignment
2019-12-12 17:06:00,210 | INFO     | 0422 | Concatenation start at2019-12-12 17:06:00.210809
2019-12-12 17:06:00,457 | INFO     | 0439 | Concatenation complete at2019-12-12 17:06:00.457177
2019-12-12 17:06:00,461 | INFO     | 0442 | merge start at2019-12-12 17:06:00.461167
2019-12-12 17:06:00,466 | INFO     | 0444 | merge end at2019-12-12 17:06:00.466155
2019-12-12 17:06:00,632 | INFO     | 0478 | Before connection establish for db
2019-12-12 17:06:00,633 | ERROR    | 0492 | Insertion into database failed for accession_no:0001193125-18-263321-(pyodbc.InterfaceError) ('IM002', '[IM002] [Microsoft][ODBC Driver Manager] Data source name not found and no default driver specified (0) (SQLDriverConnect)')
(Background on this error at: http://sqlalche.me/e/rvf5)
2019-12-12 17:06:00,633 | DEBUG    | 0065 | Exception in parsing 
2019-12-12 17:06:00,633 | DEBUG    | 0066 | local variable 'conn' referenced before assignment
2019-12-12 18:09:23,189 | DEBUG    | 0103 | Exception in replacing empty
2019-12-12 18:09:28,147 | DEBUG    | 0103 | Exception in replacing empty
2019-12-12 18:09:28,152 | DEBUG    | 0103 | Exception in replacing empty
2019-12-12 18:35:58,979 | INFO     | 0422 | Concatenation start at2019-12-12 18:35:58.979354
2019-12-12 18:36:00,217 | INFO     | 0439 | Concatenation complete at2019-12-12 18:36:00.217038
2019-12-12 18:36:00,233 | INFO     | 0442 | merge start at2019-12-12 18:36:00.233992
2019-12-12 18:36:00,272 | INFO     | 0444 | merge end at2019-12-12 18:36:00.272888
2019-12-12 18:36:01,460 | INFO     | 0478 | Before connection establish for db
2019-12-12 18:36:01,462 | ERROR    | 0492 | Insertion into database failed for accession_no:0001193125-18-263728-(pyodbc.InterfaceError) ('IM002', '[IM002] [Microsoft][ODBC Driver Manager] Data source name not found and no default driver specified (0) (SQLDriverConnect)')
(Background on this error at: http://sqlalche.me/e/rvf5)
2019-12-12 18:36:01,462 | DEBUG    | 0065 | Exception in parsing 
2019-12-12 18:36:01,462 | DEBUG    | 0066 | local variable 'conn' referenced before assignment
2019-12-12 19:19:08,074 | DEBUG    | 0103 | Exception in replacing empty
2019-12-12 19:19:12,666 | DEBUG    | 0103 | Exception in replacing empty
2019-12-12 19:19:12,676 | DEBUG    | 0103 | Exception in replacing empty
2019-12-12 19:52:38,812 | DEBUG    | 0103 | Exception in replacing empty
2019-12-12 19:52:43,452 | DEBUG    | 0103 | Exception in replacing empty
2019-12-12 19:52:43,461 | DEBUG    | 0103 | Exception in replacing empty
